Workbook

Sheet BAGACEIRAS
A1: PV | B1: Item | C1: O.S. | D1: Item2 | E1: Cliente | F1: Peça | G1: Seq. | H1: Descrição | I1: Qtde. | J1: Prazo Fundido | K1: Semana Fundido | L1: Pz Fundido Real | M1: Prazo Entrega | N1: Pz Entrega Real | O1: Dias Falta2 | P1: Indicador | Q1: Semana Entrega | R1: CONDIÇÃO | S1: Desenho Previsão | T1: Des. | U1: Perfil | V1: Serrar | W1: S. Dura | X1: Encaixe | Y1: Fur. | Z1: Acab. | AA1: Liber. | AB1: Status Us. | AC1: Obs. | AD1: Plainar Facear | AE1: Serrar2 | AF1: Solda Dura2 | AG1: Encaixe / Furação | AH1: Acabam./ Inspeção
A2: 2199 | B2: 1 | C2: 27512 | D2: 1 | E2: Raizen Energia S.A - Bonfim | F2: 956055 | G2: 1 | H2: BAGACEIRA 78" | I2: 1 | J2: 46178 | K2: =WEEKNUM(Tabela1[[#This Row],[Prazo Fundido]]) -> 23 | L2: 46175 | M2: 46213 | N2: 46199 | O2: =Tabela1[[#This Row],[Prazo Entrega]]-TODAY() -> -6 | P2: =IF(O2<0,"ATRASADO",IF(O2<=15,"ATENÇÃO","NO PRAZO")) -> ATRASADO | Q2: =WEEKNUM(Tabela1[[#This Row],[Prazo Entrega]],1) -> 28 | R2: c/ usinagem | S2: OK | T2: OK | U2: OK | V2: OK | W2: - | X2: OK | Y2: OK | Z2: OK | AA2: OK | AB2: AG. COLETAR | AD2: 24 | AE2: =Tabela1[[#This Row],[Plainar Facear]]+1 -> 25 | AF2: n/a | AG2: =Tabela1[[#This Row],[Serrar2]]+1 -> 26 | AH2: =Tabela1[[#This Row],[Encaixe / Furação]]+1 -> 27
A3: 2199 | B3: 2 | C3: 27512 | D3: 2 | E3: Raizen Energia S.A - Bonfim | F3: 956056 | G3: 1 | H3: BAGACEIRA 78" | I3: 1 | J3: 46178 | K3: =WEEKNUM(Tabela1[[#This Row],[Prazo Fundido]]) -> 23 | L3: 46192 | M3: 46220 | O3: =Tabela1[[#This Row],[Prazo Entrega]]-TODAY() -> 1 | P3: =IF(O3<0,"ATRASADO",IF(O3<=15,"ATENÇÃO","NO PRAZO")) -> ATENÇÃO | Q3: =WEEKNUM(Tabela1[[#This Row],[Prazo Entrega]],1) -> 29 | R3: c/ usinagem | S3: OK | T3: OK | U3: OK | V3: OK | W3: - | X3: OK | Y3: OK | Z3: AND | AA3: AG | AB3: =IF(L3="","AG. FUNDIDO",IF(U3="AG","AG. USINAGEM","EM USINAGEM")) -> EM USINAGEM | AD3: 24 | AE3: =Tabela1[[#This Row],[Plainar Facear]]+1 -> 25 | AF3: n/a | AG3: =Tabela1[[#This Row],[Serrar2]]+1 -> 26 | AH3: =Tabela1[[#This Row],[Encaixe / Furação]]+1 -> 27
A4: 2199 | B4: 3 | C4: 27512 | D4: 3 | E4: Raizen Energia S.A - Bonfim | F4: 956057 | G4: 1 | H4: BAGACEIRA 78" | I4: 1 | J4: 46178 | K4: =WEEKNUM(Tabela1[[#This Row],[Prazo Fundido]]) -> 23 | L4: 46192 | M4: 46213 | N4: 46199 | O4: =Tabela1[[#This Row],[Prazo Entrega]]-TODAY() -> -6 | P4: =IF(O4<0,"ATRASADO",IF(O4<=15,"ATENÇÃO","NO PRAZO")) -> ATRASADO | Q4: =WEEKNUM(Tabela1[[#This Row],[Prazo Entrega]],1) -> 28 | R4: c/ usinagem | S4: OK | T4: OK | U4: OK | V4: OK | W4: - | X4: OK | Y4: OK | Z4: OK | AA4: AND | AB4: EM INSPEÇÃO | AD4: 24 | AE4: =Tabela1[[#This Row],[Plainar Facear]]+1 -> 25 | AF4: n/a | AG4: =Tabela1[[#This Row],[Serrar2]]+1 -> 26 | AH4: =Tabela1[[#This Row],[Encaixe / Furação]]+1 -> 27
A5: 2199 | B5: 4 | C5: 27512 | D5: 4 | E5: Raizen Energia S.A - Bonfim | F5: 956058 | G5: 1 | H5: BAGACEIRA 78" | I5: 1 | J5: 46178 | K5: =WEEKNUM(Tabela1[[#This Row],[Prazo Fundido]]) -> 23 | L5: 46192 | M5: 46227 | O5: =Tabela1[[#This Row],[Prazo Entrega]]-TODAY() -> 8 | P5: =IF(O5<0,"ATRASADO",IF(O5<=15,"ATENÇÃO","NO PRAZO")) -> ATENÇÃO | Q5: =WEEKNUM(Tabela1[[#This Row],[Prazo Entrega]],1) -> 30 | R5: c/ usinagem | S5: OK | T5: OK | U5: OK | V5: OK | W5: - | X5: OK | Y5: AG | Z5: AG | AA5: AG | AB5: =IF(L5="","AG. FUNDIDO",IF(U5="AG","AG. USINAGEM","EM USINAGEM")) -> EM USINAGEM | AD5: 24 | AE5: =Tabela1[[#This Row],[Plainar Facear]]+1 -> 25 | AF5: n/a | AG5: =Tabela1[[#This Row],[Serrar2]]+1 -> 26 | AH5: =Tabela1[[#This Row],[Encaixe / Furação]]+1 -> 27
A6: 2199 | B6: 5 | C6: 27512 | D6: 5 | E6: Raizen Energia S.A - Bonfim | F6: 956059 | G6: 1 | H6: BAGACEIRA 78" | I6: 1 | J6: 46178 | K6: =WEEKNUM(Tabela1[[#This Row],[Prazo Fundido]]) -> 23 | L6: 46192 | M6: 46227 | O6: =Tabela1[[#This Row],[Prazo Entrega]]-TODAY() -> 8 | P6: =IF(O6<0,"ATRASADO",IF(O6<=15,"ATENÇÃO","NO PRAZO")) -> ATENÇÃO | Q6: =WEEKNUM(Tabela1[[#This Row],[Prazo Entrega]],1) -> 30 | R6: c/ usinagem | S6: OK | T6: OK | U6: OK | V6: OK | W6: - | X6: OK | Y6: AG | Z6: AG | AA6: AG | AB6: =IF(L6="","AG. FUNDIDO",IF(U6="AG","AG. USINAGEM","EM USINAGEM")) -> EM USINAGEM | AC6: RNC 13891 - EXCESSO DE SOBREMETAL | AD6: 24 | AE6: =Tabela1[[#This Row],[Plainar Facear]]+1 -> 25 | AF6: n/a | AG6: =Tabela1[[#This Row],[Serrar2]]+1 -> 26 | AH6: =Tabela1[[#This Row],[Encaixe / Furação]]+1 -> 27
A7: 2199 | B7: 6 | C7: 27512 | D7: 6 | E7: Raizen Energia S.A - Bonfim | F7: 956060 | G7: 1 | H7: BAGACEIRA 78" | I7: 1 | J7: 46178 | K7: =WEEKNUM(Tabela1[[#This Row],[Prazo Fundido]]) -> 23 | L7: 46188 | M7: 46220 | O7: =Tabela1[[#This Row],[Prazo Entrega]]-TODAY() -> 1 | P7: =IF(O7<0,"ATRASADO",IF(O7<=15,"ATENÇÃO","NO PRAZO")) -> ATENÇÃO | Q7: =WEEKNUM(Tabela1[[#This Row],[Prazo Entrega]],1) -> 29 | R7: c/ usinagem | S7: OK | T7: OK | U7: OK | V7: OK | W7: - | X7: OK | Y7: OK | Z7: AND | AA7: AG | AB7: =IF(L7="","AG. FUNDIDO",IF(U7="AG","AG. USINAGEM","EM USINAGEM")) -> EM USINAGEM | AD7: 24 | AE7: =Tabela1[[#This Row],[Plainar Facear]]+1 -> 25 | AF7: n/a | AG7: =Tabela1[[#This Row],[Serrar2]]+1 -> 26 | AH7: =Tabela1[[#This Row],[Encaixe / Furação]]+1 -> 27
A8: 2199 | B8: 7 | C8: 27512 | D8: 7 | E8: Raizen Energia S.A - Bonfim | F8: 956061 | G8: 1 | H8: BAGACEIRA 78" | I8: 1 | J8: 46178 | K8: =WEEKNUM(Tabela1[[#This Row],[Prazo Fundido]]) -> 23 | L8: 46171 | M8: 46213 | N8: 46199 | O8: =Tabela1[[#This Row],[Prazo Entrega]]-TODAY() -> -6 | P8: =IF(O8<0,"ATRASADO",IF(O8<=15,"ATENÇÃO","NO PRAZO")) -> ATRASADO | Q8: =WEEKNUM(Tabela1[[#This Row],[Prazo Entrega]],1) -> 28 | R8: c/ usinagem | S8: OK | T8: OK | U8: OK | V8: OK | W8: - | X8: OK | Y8: OK | Z8: OK | AA8: OK | AB8: AG. COLETAR | AD8: 23 | AE8: =Tabela1[[#This Row],[Plainar Facear]]+1 -> 24 | AF8: n/a | AG8: =Tabela1[[#This Row],[Serrar2]]+1 -> 25 | AH8: =Tabela1[[#This Row],[Encaixe / Furação]]+1 -> 26
A9: 2199 | B9: 8 | C9: 27512 | D9: 8 | E9: Raizen Energia S.A - Bonfim | F9: 956062 | G9: 1 | H9: BAGACEIRA 78" | I9: 1 | J9: 46178 | K9: =WEEKNUM(Tabela1[[#This Row],[Prazo Fundido]]) -> 23 | L9: 46171 | M9: 46213 | N9: 46199 | O9: =Tabela1[[#This Row],[Prazo Entrega]]-TODAY() -> -6 | P9: =IF(O9<0,"ATRASADO",IF(O9<=15,"ATENÇÃO","NO PRAZO")) -> ATRASADO | Q9: =WEEKNUM(Tabela1[[#This Row],[Prazo Entrega]],1) -> 28 | R9: c/ usinagem | S9: OK | T9: OK | U9: OK | V9: OK | W9: - | X9: OK | Y9: OK | Z9: OK | AA9: OK | AB9: AG. COLETAR | AD9: 23 | AE9: =Tabela1[[#This Row],[Plainar Facear]]+1 -> 24 | AF9: n/a | AG9: =Tabela1[[#This Row],[Serrar2]]+1 -> 25 | AH9: =Tabela1[[#This Row],[Encaixe / Furação]]+1 -> 26
A10: 2199 | B10: 9 | C10: 27512 | D10: 9 | E10: Raizen Energia S.A - Bonfim | F10: 956063 | G10: 1 | H10: BAGACEIRA 78" | I10: 1 | J10: 46178 | K10: =WEEKNUM(Tabela1[[#This Row],[Prazo Fundido]]) -> 23 | L10: 46171 | M10: 46213 | N10: 46199 | O10: =Tabela1[[#This Row],[Prazo Entrega]]-TODAY() -> -6 | P10: =IF(O10<0,"ATRASADO",IF(O10<=15,"ATENÇÃO","NO PRAZO")) -> ATRASADO | Q10: =WEEKNUM(Tabela1[[#This Row],[Prazo Entrega]],1) -> 28 | R10: c/ usinagem | S10: OK | T10: OK | U10: OK | V10: OK | W10: - | X10: OK | Y10: OK | Z10: OK | AA10: OK | AB10: AG. COLETAR | AD10: 23 | AE10: =Tabela1[[#This Row],[Plainar Facear]]+1 -> 24 | AF10: n/a | AG10: =Tabela1[[#This Row],[Serrar2]]+1 -> 25 | AH10: =Tabela1[[#This Row],[Encaixe / Furação]]+1 -> 26
A11: 2199 | B11: 10 | C11: 27512 | D11: 10 | E11: Raizen Energia S.A - Bonfim | F11: 956064 | G11: 1 | H11: BAGACEIRA 78" | I11: 1 | J11: 46178 | K11: =WEEKNUM(Tabela1[[#This Row],[Prazo Fundido]]) -> 23 | L11: 46171 | M11: 46213 | N11: 46199 | O11: =Tabela1[[#This Row],[Prazo Entrega]]-TODAY() -> -6 | P11: =IF(O11<0,"ATRASADO",IF(O11<=15,"ATENÇÃO","NO PRAZO")) -> ATRASADO | Q11: =WEEKNUM(Tabela1[[#This Row],[Prazo Entrega]],1) -> 28 | R11: c/ usinagem | S11: OK | T11: OK | U11: OK | V11: OK | W11: - | X11: OK | Y11: OK | Z11: OK | AA11: OK | AB11: AG. COLETAR | AD11: 23 | AE11: =Tabela1[[#This Row],[Plainar Facear]]+1 -> 24 | AF11: n/a | AG11: =Tabela1[[#This Row],[Serrar2]]+1 -> 25 | AH11: =Tabela1[[#This Row],[Encaixe / Furação]]+1 -> 26
A12: 2201 | B12: 1 | C12: 27513 | D12: 1 | E12: Raizen Energia S.A. - Costa Pinto | F12: 1148030 | G12: 1 | H12: BAGACEIRA 78" | I12: 1 | J12: 46178 | K12: =WEEKNUM(Tabela1[[#This Row],[Prazo Fundido]]) -> 23 | L12: 46192 | M12: 46220 | O12: =Tabela1[[#This Row],[Prazo Entrega]]-TODAY() -> 1 | P12: =IF(O12<0,"ATRASADO",IF(O12<=15,"ATENÇÃO","NO PRAZO")) -> ATENÇÃO | Q12: =WEEKNUM(Tabela1[[#This Row],[Prazo Entrega]],1) -> 29 | R12: c/ usinagem | S12: OK | T12: OK | U12: OK | V12: OK | W12: - | X12: OK | Y12: OK | Z12: AND | AA12: AG | AB12: =IF(L12="","AG. FUNDIDO",IF(U12="AG","AG. USINAGEM","EM USINAGEM")) -> EM USINAGEM | AD12: 26 | AE12: =Tabela1[[#This Row],[Plainar Facear]]+1 -> 27 | AF12: n/a | AG12: =Tabela1[[#This Row],[Serrar2]]+1 -> 28 | AH12: =Tabela1[[#This Row],[Encaixe / Furação]]+1 -> 29
A13: 2201 | B13: 2 | C13: 27513 | D13: 2 | E13: Raizen Energia S.A. - Costa Pinto | F13: 1148031 | G13: 1 | H13: BAGACEIRA 78" | I13: 1 | J13: 46178 | K13: =WEEKNUM(Tabela1[[#This Row],[Prazo Fundido]]) -> 23 | L13: 46192 | M13: 46220 | O13: =Tabela1[[#This Row],[Prazo Entrega]]-TODAY() -> 1 | P13: =IF(O13<0,"ATRASADO",IF(O13<=15,"ATENÇÃO","NO PRAZO")) -> ATENÇÃO | Q13: =WEEKNUM(Tabela1[[#This Row],[Prazo Entrega]],1) -> 29 | R13: c/ usinagem | S13: OK | T13: OK | U13: OK | V13: OK | W13: - | X13: OK | Y13: OK | Z13: AND | AA13: AG | AB13: =IF(L13="","AG. FUNDIDO",IF(U13="AG","AG. USINAGEM","EM USINAGEM")) -> EM USINAGEM | AD13: 26 | AE13: =Tabela1[[#This Row],[Plainar Facear]]+1 -> 27 | AF13: n/a | AG13: =Tabela1[[#This Row],[Serrar2]]+1 -> 28 | AH13: =Tabela1[[#This Row],[Encaixe / Furação]]+1 -> 29
A14: 2201 | B14: 3 | C14: 27513 | D14: 3 | E14: Raizen Energia S.A. - Costa Pinto | F14: 1148032 | G14: 1 | H14: BAGACEIRA 78" | I14: 1 | J14: 46178 | K14: =WEEKNUM(Tabela1[[#This Row],[Prazo Fundido]]) -> 23 | L14: 46189 | M14: 46220 | O14: =Tabela1[[#This Row],[Prazo Entrega]]-TODAY() -> 1 | P14: =IF(O14<0,"ATRASADO",IF(O14<=15,"ATENÇÃO","NO PRAZO")) -> ATENÇÃO | Q14: =WEEKNUM(Tabela1[[#This Row],[Prazo Entrega]],1) -> 29 | R14: c/ usinagem | S14: OK | T14: OK | U14: OK | V14: OK | W14: - | X14: OK | Y14: OK | Z14: AND | AA14: AG | AB14: =IF(L14="","AG. FUNDIDO",IF(U14="AG","AG. USINAGEM","EM USINAGEM")) -> EM USINAGEM | AD14: 26 | AE14: =Tabela1[[#This Row],[Plainar Facear]]+1 -> 27 | AF14: n/a | AG14: =Tabela1[[#This Row],[Serrar2]]+1 -> 28 | AH14: =Tabela1[[#This Row],[Encaixe / Furação]]+1 -> 29
A15: 2199 | B15: 11 | C15: 27512 | D15: 11 | E15: Raizen Energia S.A - Bonfim | F15: 956065 | G15: 1 | H15: BAGACEIRA 78" | I15: 1 | J15: 46178 | K15: =WEEKNUM(Tabela1[[#This Row],[Prazo Fundido]]) -> 23 | L15: 46175 | M15: 46220 | O15: =Tabela1[[#This Row],[Prazo Entrega]]-TODAY() -> 1 | P15: =IF(O15<0,"ATRASADO",IF(O15<=15,"ATENÇÃO","NO PRAZO")) -> ATENÇÃO | Q15: =WEEKNUM(Tabela1[[#This Row],[Prazo Entrega]],1) -> 29 | R15: c/ usinagem | S15: OK | T15: OK | U15: OK | V15: AG | W15: - | X15: AG | Y15: AG | Z15: AG | AA15: AG | AB15: =IF(L15="","AG. FUNDIDO",IF(U15="AG","AG. USINAGEM","EM USINAGEM")) -> EM USINAGEM | AC15: PARALISADO PARA SERRAR DENTES. LIBERADO SERRAR DIA 07/07/2026 NECESSARIO REUSINAR PERFIL | AD15: 26 | AE15: =Tabela1[[#This Row],[Plainar Facear]]+1 -> 27 | AF15: n/a | AG15: =Tabela1[[#This Row],[Serrar2]]+1 -> 28 | AH15: =Tabela1[[#This Row],[Encaixe / Furação]]+1 -> 29
A16: 2199 | B16: 12 | C16: 27512 | D16: 12 | E16: Raizen Energia S.A - Bonfim | F16: 956066 | G16: 1 | H16: BAGACEIRA 78" | I16: 1 | J16: 46178 | K16: =WEEKNUM(Tabela1[[#This Row],[Prazo Fundido]]) -> 23 | L16: 46175 | M16: 46227 | O16: =Tabela1[[#This Row],[Prazo Entrega]]-TODAY() -> 8 | P16: =IF(O16<0,"ATRASADO",IF(O16<=15,"ATENÇÃO","NO PRAZO")) -> ATENÇÃO | Q16: =WEEKNUM(Tabela1[[#This Row],[Prazo Entrega]],1) -> 30 | R16: c/ usinagem | S16: OK | T16: OK | U16: OK | V16: OK | W16: - | X16: OK | Y16: AG | Z16: AG | AA16: AG | AB16: EM USINAGEM | AD16: 26 | AE16: =Tabela1[[#This Row],[Plainar Facear]]+1 -> 27 | AF16: n/a | AG16: =Tabela1[[#This Row],[Serrar2]]+1 -> 28 | AH16: =Tabela1[[#This Row],[Encaixe / Furação]]+1 -> 29
A17: 2201 | B17: 4 | C17: 27513 | D17: 4 | E17: Raizen Energia S.A. - Costa Pinto | F17: 1148033 | G17: 1 | H17: BAGACEIRA 78" | I17: 1 | J17: 46185 | K17: =WEEKNUM(Tabela1[[#This Row],[Prazo Fundido]]) -> 24 | L17: 46175 | M17: 46213 | N17: 46199 | O17: =Tabela1[[#This Row],[Prazo Entrega]]-TODAY() -> -6 | P17: =IF(O17<0,"ATRASADO",IF(O17<=15,"ATENÇÃO","NO PRAZO")) -> ATRASADO | Q17: =WEEKNUM(Tabela1[[#This Row],[Prazo Entrega]],1) -> 28 | R17: c/ usinagem | S17: OK | T17: OK | U17: OK | V17: OK | W17: - | X17: OK | Y17: OK | Z17: OK | AA17: OK | AB17: AG. COLETAR | AD17: 26 | AE17: =Tabela1[[#This Row],[Plainar Facear]]+1 -> 27 | AF17: n/a | AG17: =Tabela1[[#This Row],[Serrar2]]+1 -> 28 | AH17: =Tabela1[[#This Row],[Encaixe / Furação]]+1 -> 29
A18: 2201 | B18: 5 | C18: 27513 | D18: 5 | E18: Raizen Energia S.A. - Costa Pinto | F18: 1148034 | G18: 1 | H18: BAGACEIRA 78" | I18: 1 | J18: 46185 | K18: =WEEKNUM(Tabela1[[#This Row],[Prazo Fundido]]) -> 24 | L18: 46175 | M18: 46213 | N18: 46199 | O18: =Tabela1[[#This Row],[Prazo Entrega]]-TODAY() -> -6 | P18: =IF(O18<0,"ATRASADO",IF(O18<=15,"ATENÇÃO","NO PRAZO")) -> ATRASADO | Q18: =WEEKNUM(Tabela1[[#This Row],[Prazo Entrega]],1) -> 28 | R18: c/ usinagem | S18: OK | T18: OK | U18: OK | V18: OK | W18: - | X18: OK | Y18: OK | Z18: OK | AA18: OK | AB18: AG. COLETAR | AD18: 26 | AE18: =Tabela1[[#This Row],[Plainar Facear]]+1 -> 27 | AF18: n/a | AG18: =Tabela1[[#This Row],[Serrar2]]+1 -> 28 | AH18: =Tabela1[[#This Row],[Encaixe / Furação]]+1 -> 29
A19: 2201 | B19: 6 | C19: 27513 | D19: 6 | E19: Raizen Energia S.A. - Costa Pinto | F19: 1148035 | G19: 1 | H19: BAGACEIRA 78" | I19: 1 | J19: 46185 | K19: =WEEKNUM(Tabela1[[#This Row],[Prazo Fundido]]) -> 24 | L19: 46175 | M19: 46213 | N19: 46199 | O19: =Tabela1[[#This Row],[Prazo Entrega]]-TODAY() -> -6 | P19: =IF(O19<0,"ATRASADO",IF(O19<=15,"ATENÇÃO","NO PRAZO")) -> ATRASADO | Q19: =WEEKNUM(Tabela1[[#This Row],[Prazo Entrega]],1) -> 28 | R19: c/ usinagem | S19: OK | T19: OK | U19: OK | V19: OK | W19: - | X19: OK | Y19: OK | Z19: OK | AA19: OK | AB19: AG. COLETAR | AD19: 26 | AE19: =Tabela1[[#This Row],[Plainar Facear]]+1 -> 27 | AF19: n/a | AG19: =Tabela1[[#This Row],[Serrar2]]+1 -> 28 | AH19: =Tabela1[[#This Row],[Encaixe / Furação]]+1 -> 29
A20: 2201 | B20: 7 | C20: 27513 | D20: 7 | E20: Raizen Energia S.A. - Costa Pinto | F20: 1148036 | G20: 1 | H20: BAGACEIRA 78" | I20: 1 | J20: 46185 | K20: =WEEKNUM(Tabela1[[#This Row],[Prazo Fundido]]) -> 24 | L20: 46206 | M20: 46227 | O20: =Tabela1[[#This Row],[Prazo Entrega]]-TODAY() -> 8 | P20: =IF(O20<0,"ATRASADO",IF(O20<=15,"ATENÇÃO","NO PRAZO")) -> ATENÇÃO | Q20: =WEEKNUM(Tabela1[[#This Row],[Prazo Entrega]],1) -> 30 | R20: c/ usinagem | S20: OK | T20: OK | U20: OK | V20: OK | W20: - | X20: AND | Y20: AG | Z20: AG | AA20: AG | AB20: =IF(L20="","AG. FUNDIDO",IF(U20="AG","AG. USINAGEM","EM USINAGEM")) -> EM USINAGEM | AD20: 26 | AE20: =Tabela1[[#This Row],[Plainar Facear]]+1 -> 27 | AF20: n/a | AG20: =Tabela1[[#This Row],[Serrar2]]+1 -> 28 | AH20: =Tabela1[[#This Row],[Encaixe / Furação]]+1 -> 29
A21: 2201 | B21: 8 | C21: 27513 | D21: 8 | E21: Raizen Energia S.A. - Costa Pinto | F21: 1148037 | G21: 1 | H21: BAGACEIRA 78" | I21: 1 | J21: 46185 | K21: =WEEKNUM(Tabela1[[#This Row],[Prazo Fundido]]) -> 24 | L21: 46206 | M21: 46220 | O21: =Tabela1[[#This Row],[Prazo Entrega]]-TODAY() -> 1 | P21: =IF(O21<0,"ATRASADO",IF(O21<=15,"ATENÇÃO","NO PRAZO")) -> ATENÇÃO | Q21: =WEEKNUM(Tabela1[[#This Row],[Prazo Entrega]],1) -> 29 | R21: c/ usinagem | S21: OK | T21: OK | U21: OK | V21: AND | W21: - | X21: AG | Y21: AG | Z21: AG | AA21: AG | AB21: =IF(L21="","AG. FUNDIDO",IF(U21="AG","AG. USINAGEM","EM USINAGEM")) -> EM USINAGEM | AD21: 26 | AE21: =Tabela1[[#This Row],[Plainar Facear]]+1 -> 27 | AF21: n/a | AG21: =Tabela1[[#This Row],[Serrar2]]+1 -> 28 | AH21: =Tabela1[[#This Row],[Encaixe / Furação]]+1 -> 29
A22: 2203 | B22: 1 | C22: 27515 | D22: 1 | E22: Raizen Energia S.A - Ipaussu | F22: 958022 | G22: 1 | H22: BAGACEIRA 78" | I22: 1 | J22: 46185 | K22: =WEEKNUM(Tabela1[[#This Row],[Prazo Fundido]]) -> 24 | L22: 46189 | M22: 46227 | O22: =Tabela1[[#This Row],[Prazo Entrega]]-TODAY() -> 8 | P22: =IF(O22<0,"ATRASADO",IF(O22<=15,"ATENÇÃO","NO PRAZO")) -> ATENÇÃO | Q22: =WEEKNUM(Tabela1[[#This Row],[Prazo Entrega]],1) -> 30 | R22: c/ usinagem | S22: OK | T22: OK | U22: AND | V22: AG | W22: - | X22: AG | Y22: AG | Z22: AG | AA22: AG | AB22: =IF(L22="","AG. FUNDIDO",IF(U22="AG","AG. USINAGEM","EM USINAGEM")) -> EM USINAGEM | AD22: 25 | AE22: =Tabela1[[#This Row],[Plainar Facear]]+1 -> 26 | AF22: n/a | AG22: =Tabela1[[#This Row],[Serrar2]]+1 -> 27 | AH22: =Tabela1[[#This Row],[Encaixe / Furação]]+1 -> 28
A23: 2203 | B23: 2 | C23: 27515 | D23: 2 | E23: Raizen Energia S.A - Ipaussu | F23: 958023 | G23: 1 | H23: BAGACEIRA 78" | I23: 1 | J23: 46185 | K23: =WEEKNUM(Tabela1[[#This Row],[Prazo Fundido]]) -> 24 | L23: 46190 | M23: 46227 | O23: =Tabela1[[#This Row],[Prazo Entrega]]-TODAY() -> 8 | P23: =IF(O23<0,"ATRASADO",IF(O23<=15,"ATENÇÃO","NO PRAZO")) -> ATENÇÃO | Q23: =WEEKNUM(Tabela1[[#This Row],[Prazo Entrega]],1) -> 30 | R23: c/ usinagem | S23: OK | T23: OK | U23: AG | V23: AG | W23: - | X23: AG | Y23: AG | Z23: AG | AA23: AG | AB23: =IF(L23="","AG. FUNDIDO",IF(U23="AG","AG. USINAGEM","EM USINAGEM")) -> AG. USINAGEM | AD23: 25 | AE23: =Tabela1[[#This Row],[Plainar Facear]]+1 -> 26 | AF23: n/a | AG23: =Tabela1[[#This Row],[Serrar2]]+1 -> 27 | AH23: =Tabela1[[#This Row],[Encaixe / Furação]]+1 -> 28
A24: 2227 | B24: 14 | C24: 27528 | D24: 14 | E24: MS Internacional | F24: 1454055 | G24: 1 | H24: BAGACEIRA 84" | I24: 1 | J24: 46190 | K24: =WEEKNUM(Tabela1[[#This Row],[Prazo Fundido]]) -> 25 | L24: 46184 | M24: 46210 | O24: =Tabela1[[#This Row],[Prazo Entrega]]-TODAY() -> -9 | P24: OK | Q24: =WEEKNUM(Tabela1[[#This Row],[Prazo Entrega]],1) -> 28 | R24: c/ usinagem | S24: OK | T24: OK | U24: OK | V24: OK | W24: - | X24: OK | Y24: OK | Z24: OK | AA24: OK | AB24: AG. COLETAR | AD24: 25 | AE24: =Tabela1[[#This Row],[Plainar Facear]]+1 -> 26 | AF24: n/a | AG24: =Tabela1[[#This Row],[Serrar2]]+1 -> 27 | AH24: =Tabela1[[#This Row],[Encaixe / Furação]]+1 -> 28
A25: 2227 | B25: 15 | C25: 27528 | D25: 15 | E25: MS Internacional | F25: 1454055 | G25: 2 | H25: BAGACEIRA 84" | I25: 1 | J25: 46190 | K25: =WEEKNUM(Tabela1[[#This Row],[Prazo Fundido]]) -> 25 | L25: 46184 | M25: 46210 | O25: =Tabela1[[#This Row],[Prazo Entrega]]-TODAY() -> -9 | P25: OK | Q25: =WEEKNUM(Tabela1[[#This Row],[Prazo Entrega]],1) -> 28 | R25: c/ usinagem | S25: OK | T25: OK | U25: OK | V25: OK | W25: - | X25: OK | Y25: OK | Z25: OK | AA25: OK | AB25: AG. COLETAR | AD25: 25 | AE25: =Tabela1[[#This Row],[Plainar Facear]]+1 -> 26 | AF25: n/a | AG25: =Tabela1[[#This Row],[Serrar2]]+1 -> 27 | AH25: =Tabela1[[#This Row],[Encaixe / Furação]]+1 -> 28
A26: 2227 | B26: 17 | C26: 27528 | D26: 17 | E26: MS Internacional | F26: 1454056 | G26: 2 | H26: BAGACEIRA 84" | I26: 1 | J26: 46190 | K26: =WEEKNUM(Tabela1[[#This Row],[Prazo Fundido]]) -> 25 | L26: 46184 | M26: 46210 | O26: =Tabela1[[#This Row],[Prazo Entrega]]-TODAY() -> -9 | P26: OK | Q26: =WEEKNUM(Tabela1[[#This Row],[Prazo Entrega]],1) -> 28 | R26: c/ usinagem | S26: OK | T26: OK | U26: OK | V26: OK | W26: - | X26: OK | Y26: OK | Z26: OK | AA26: OK | AB26: AG. COLETAR | AD26: 25 | AE26: =Tabela1[[#This Row],[Plainar Facear]]+1 -> 26 | AF26: n/a | AG26: =Tabela1[[#This Row],[Serrar2]]+1 -> 27 | AH26: =Tabela1[[#This Row],[Encaixe / Furação]]+1 -> 28
A27: 2227 | B27: 18 | C27: 27528 | D27: 18 | E27: MS Internacional | F27: 1454056 | G27: 1 | H27: BAGACEIRA 84" | I27: 1 | J27: 46190 | K27: =WEEKNUM(Tabela1[[#This Row],[Prazo Fundido]]) -> 25 | L27: 46184 | M27: 46210 | O27: =Tabela1[[#This Row],[Prazo Entrega]]-TODAY() -> -9 | P27: OK | Q27: =WEEKNUM(Tabela1[[#This Row],[Prazo Entrega]],1) -> 28 | R27: c/ usinagem | S27: OK | T27: OK | U27: OK | V27: OK | W27: - | X27: OK | Y27: OK | Z27: OK | AA27: OK | AB27: AG. COLETAR | AD27: 25 | AE27: =Tabela1[[#This Row],[Plainar Facear]]+1 -> 26 | AF27: n/a | AG27: =Tabela1[[#This Row],[Serrar2]]+1 -> 27 | AH27: =Tabela1[[#This Row],[Encaixe / Furação]]+1 -> 28
A28: 2227 | B28: 19 | C28: 27528 | D28: 19 | E28: MS Internacional | F28: 1454057 | G28: 1 | H28: BAGACEIRA 84" | I28: 1 | J28: 46190 | K28: =WEEKNUM(Tabela1[[#This Row],[Prazo Fundido]]) -> 25 | L28: 46184 | M28: 46210 | O28: =Tabela1[[#This Row],[Prazo Entrega]]-TODAY() -> -9 | P28: OK | Q28: =WEEKNUM(Tabela1[[#This Row],[Prazo Entrega]],1) -> 28 | R28: c/ usinagem | S28: OK | T28: OK | U28: OK | V28: OK | W28: - | X28: OK | Y28: OK | Z28: OK | AA28: OK | AB28: AG. COLETAR | AD28: 25 | AE28: =Tabela1[[#This Row],[Plainar Facear]]+1 -> 26 | AF28: n/a | AG28: =Tabela1[[#This Row],[Serrar2]]+1 -> 27 | AH28: =Tabela1[[#This Row],[Encaixe / Furação]]+1 -> 28
A29: 2227 | B29: 20 | C29: 27528 | D29: 20 | E29: MS Internacional | F29: 1454057 | G29: 2 | H29: BAGACEIRA 84" | I29: 1 | J29: 46190 | K29: =WEEKNUM(Tabela1[[#This Row],[Prazo Fundido]]) -> 25 | L29: 46184 | M29: 46210 | O29: =Tabela1[[#This Row],[Prazo Entrega]]-TODAY() -> -9 | P29: OK | Q29: =WEEKNUM(Tabela1[[#This Row],[Prazo Entrega]],1) -> 28 | R29: c/ usinagem | S29: OK | T29: OK | U29: OK | V29: OK | W29: - | X29: OK | Y29: OK | Z29: OK | AA29: OK | AB29: AG. COLETAR | AD29: 25 | AE29: =Tabela1[[#This Row],[Plainar Facear]]+1 -> 26 | AF29: n/a | AG29: =Tabela1[[#This Row],[Serrar2]]+1 -> 27 | AH29: =Tabela1[[#This Row],[Encaixe / Furação]]+1 -> 28
A30: 2203 | B30: 3 | C30: 27515 | D30: 3 | E30: Raizen Energia S.A - Ipaussu | F30: 958024 | G30: 1 | H30: BAGACEIRA 78" | I30: 1 | J30: 46185 | K30: =WEEKNUM(Tabela1[[#This Row],[Prazo Fundido]]) -> 24 | L30: 46192 | M30: 46227 | O30: =Tabela1[[#This Row],[Prazo Entrega]]-TODAY() -> 8 | P30: =IF(O30<0,"ATRASADO",IF(O30<=15,"ATENÇÃO","NO PRAZO")) -> ATENÇÃO | Q30: =WEEKNUM(Tabela1[[#This Row],[Prazo Entrega]],1) -> 30 | R30: c/ usinagem | S30: OK | T30: OK | U30: OK | V30: AG | W30: - | X30: AG | Y30: AG | Z30: AG | AA30: AG | AB30: =IF(L30="","AG. FUNDIDO",IF(U30="AG","AG. USINAGEM","EM USINAGEM")) -> EM USINAGEM | AD30: 27 | AE30: =Tabela1[[#This Row],[Plainar Facear]]+1 -> 28 | AF30: n/a | AG30: =Tabela1[[#This Row],[Serrar2]]+1 -> 29 | AH30: =Tabela1[[#This Row],[Encaixe / Furação]]+1 -> 30
A31: 2202 | B31: 1 | C31: 27514 | D31: 1 | E31: Raizen Energia S.A - Diamante | F31: 1256014 | G31: 1 | H31: BAGACEIRA 78" | I31: 1 | J31: 46185 | K31: =WEEKNUM(Tabela1[[#This Row],[Prazo Fundido]]) -> 24 | L31: 46175 | M31: 46213 | N31: 46199 | O31: =Tabela1[[#This Row],[Prazo Entrega]]-TODAY() -> -6 | P31: =IF(O31<0,"ATRASADO",IF(O31<=15,"ATENÇÃO","NO PRAZO")) -> ATRASADO | Q31: =WEEKNUM(Tabela1[[#This Row],[Prazo Entrega]],1) -> 28 | R31: c/ usinagem | S31: OK | T31: OK | U31: OK | V31: OK | W31: - | X31: OK | Y31: OK | Z31: OK | AA31: OK | AB31: AG. COLETAR | AD31: 27 | AE31: =Tabela1[[#This Row],[Plainar Facear]]+1 -> 28 | AF31: n/a | AG31: =Tabela1[[#This Row],[Serrar2]]+1 -> 29 | AH31: =Tabela1[[#This Row],[Encaixe / Furação]]+1 -> 30
A32: 2202 | B32: 2 | C32: 27514 | D32: 2 | E32: Raizen Energia S.A - Diamante | F32: 1256015 | G32: 1 | H32: BAGACEIRA 78" | I32: 1 | J32: 46185 | K32: =WEEKNUM(Tabela1[[#This Row],[Prazo Fundido]]) -> 24 | L32: 46175 | M32: 46220 | O32: =Tabela1[[#This Row],[Prazo Entrega]]-TODAY() -> 1 | P32: =IF(O32<0,"ATRASADO",IF(O32<=15,"ATENÇÃO","NO PRAZO")) -> ATENÇÃO | Q32: =WEEKNUM(Tabela1[[#This Row],[Prazo Entrega]],1) -> 29 | R32: c/ usinagem | S32: OK | T32: OK | U32: OK | V32: OK | W32: - | X32: OK | Y32: OK | Z32: AND | AA32: AG | AB32: =IF(L32="","AG. FUNDIDO",IF(U32="AG","AG. USINAGEM","EM USINAGEM")) -> EM USINAGEM | AD32: 27 | AE32: =Tabela1[[#This Row],[Plainar Facear]]+1 -> 28 | AF32: n/a | AG32: =Tabela1[[#This Row],[Serrar2]]+1 -> 29 | AH32: =Tabela1[[#This Row],[Encaixe / Furação]]+1 -> 30
A33: 2202 | B33: 3 | C33: 27514 | D33: 3 | E33: Raizen Energia S.A - Diamante | F33: 1256016 | G33: 1 | H33: BAGACEIRA 78" | I33: 1 | J33: 46185 | K33: =WEEKNUM(Tabela1[[#This Row],[Prazo Fundido]]) -> 24 | L33: 46175 | M33: 46227 | O33: =Tabela1[[#This Row],[Prazo Entrega]]-TODAY() -> 8 | P33: =IF(O33<0,"ATRASADO",IF(O33<=15,"ATENÇÃO","NO PRAZO")) -> ATENÇÃO | Q33: =WEEKNUM(Tabela1[[#This Row],[Prazo Entrega]],1) -> 30 | R33: c/ usinagem | S33: OK | T33: OK | U33: OK | V33: AG | W33: - | X33: AG | Y33: AG | Z33: AG | AA33: AG | AB33: =IF(L33="","AG. FUNDIDO",IF(U33="AG","AG. USINAGEM","EM USINAGEM")) -> EM USINAGEM | AD33: 27 | AE33: =Tabela1[[#This Row],[Plainar Facear]]+1 -> 28 | AF33: n/a | AG33: =Tabela1[[#This Row],[Serrar2]]+1 -> 29 | AH33: =Tabela1[[#This Row],[Encaixe / Furação]]+1 -> 30
A34: 2202 | B34: 4 | C34: 27514 | D34: 4 | E34: Raizen Energia S.A - Diamante | F34: 1256017 | G34: 1 | H34: BAGACEIRA 78" | I34: 1 | J34: 46185 | K34: =WEEKNUM(Tabela1[[#This Row],[Prazo Fundido]]) -> 24 | L34: 46175 | M34: 46220 | O34: =Tabela1[[#This Row],[Prazo Entrega]]-TODAY() -> 1 | P34: =IF(O34<0,"ATRASADO",IF(O34<=15,"ATENÇÃO","NO PRAZO")) -> ATENÇÃO | Q34: =WEEKNUM(Tabela1[[#This Row],[Prazo Entrega]],1) -> 29 | R34: c/ usinagem | S34: OK | T34: OK | U34: OK | V34: OK | W34: - | X34: OK | Y34: OK | Z34: AND | AA34: AG | AB34: =IF(L34="","AG. FUNDIDO",IF(U34="AG","AG. USINAGEM","EM USINAGEM")) -> EM USINAGEM | AD34: 27 | AE34: =Tabela1[[#This Row],[Plainar Facear]]+1 -> 28 | AF34: n/a | AG34: =Tabela1[[#This Row],[Serrar2]]+1 -> 29 | AH34: =Tabela1[[#This Row],[Encaixe / Furação]]+1 -> 30
A35: 2202 | B35: 5 | C35: 27514 | D35: 5 | E35: Raizen Energia S.A - Diamante | F35: 1256018 | G35: 1 | H35: BAGACEIRA 78" | I35: 1 | J35: 46185 | K35: =WEEKNUM(Tabela1[[#This Row],[Prazo Fundido]]) -> 24 | L35: 46175 | M35: 46227 | O35: =Tabela1[[#This Row],[Prazo Entrega]]-TODAY() -> 8 | P35: =IF(O35<0,"ATRASADO",IF(O35<=15,"ATENÇÃO","NO PRAZO")) -> ATENÇÃO | Q35: =WEEKNUM(Tabela1[[#This Row],[Prazo Entrega]],1) -> 30 | R35: c/ usinagem | S35: OK | T35: OK | U35: OK | V35: OK | W35: - | X35: AG | Y35: AG | Z35: AG | AA35: AG | AB35: =IF(L35="","AG. FUNDIDO",IF(U35="AG","AG. USINAGEM","EM USINAGEM")) -> EM USINAGEM | AD35: 27 | AE35: =Tabela1[[#This Row],[Plainar Facear]]+1 -> 28 | AF35: n/a | AG35: =Tabela1[[#This Row],[Serrar2]]+1 -> 29 | AH35: =Tabela1[[#This Row],[Encaixe / Furação]]+1 -> 30
A36: 2201 | B36: 9 | C36: 27513 | D36: 9 | E36: Raizen Energia S.A. - Costa Pinto | F36: 1148038 | G36: 1 | H36: BAGACEIRA 78" | I36: 1 | J36: 46185 | K36: =WEEKNUM(Tabela1[[#This Row],[Prazo Fundido]]) -> 24 | L36: 46189 | M36: 46220 | O36: =Tabela1[[#This Row],[Prazo Entrega]]-TODAY() -> 1 | P36: =IF(O36<0,"ATRASADO",IF(O36<=15,"ATENÇÃO","NO PRAZO")) -> ATENÇÃO | Q36: =WEEKNUM(Tabela1[[#This Row],[Prazo Entrega]],1) -> 29 | R36: c/ usinagem | S36: OK | T36: OK | U36: OK | V36: OK | W36: - | X36: OK | Y36: OK | Z36: AND | AA36: AG | AB36: =IF(L36="","AG. FUNDIDO",IF(U36="AG","AG. USINAGEM","EM USINAGEM")) -> EM USINAGEM | AD36: 27 | AE36: =Tabela1[[#This Row],[Plainar Facear]]+1 -> 28 | AF36: n/a | AG36: =Tabela1[[#This Row],[Serrar2]]+1 -> 29 | AH36: =Tabela1[[#This Row],[Encaixe / Furação]]+1 -> 30
A37: 2201 | B37: 10 | C37: 27513 | D37: 10 | E37: Raizen Energia S.A. - Costa Pinto | F37: 1148039 | G37: 1 | H37: BAGACEIRA 84" | I37: 1 | J37: 46185 | K37: =WEEKNUM(Tabela1[[#This Row],[Prazo Fundido]]) -> 24 | L37: 46192 | M37: 46227 | O37: =Tabela1[[#This Row],[Prazo Entrega]]-TODAY() -> 8 | P37: =IF(O37<0,"ATRASADO",IF(O37<=15,"ATENÇÃO","NO PRAZO")) -> ATENÇÃO | Q37: =WEEKNUM(Tabela1[[#This Row],[Prazo Entrega]],1) -> 30 | R37: c/ usinagem | S37: OK | T37: OK | U37: AG | V37: AG | W37: - | X37: AG | Y37: AG | Z37: AG | AA37: AG | AB37: =IF(L37="","AG. FUNDIDO",IF(U37="AG","AG. USINAGEM","EM USINAGEM")) -> AG. USINAGEM | AC37: RNC 13892 - BAGACEIRA CÓD. 1148039 - REFUGADA POR FALTA DE MATERIAL. | AD37: 27 | AE37: =Tabela1[[#This Row],[Plainar Facear]]+1 -> 28 | AF37: n/a | AG37: =Tabela1[[#This Row],[Serrar2]]+1 -> 29 | AH37: =Tabela1[[#This Row],[Encaixe / Furação]]+1 -> 30
A38: 2205 | B38: 1 | C38: 27517 | D38: 1 | E38: Raizen Energia S.A. - Paraiso | F38: 1483008 | G38: 1 | H38: BAGACEIRA 78" | I38: 1 | J38: 46192 | K38: =WEEKNUM(Tabela1[[#This Row],[Prazo Fundido]]) -> 25 | L38: 46175 | M38: 46234 | O38: =Tabela1[[#This Row],[Prazo Entrega]]-TODAY() -> 15 | P38: =IF(O38<0,"ATRASADO",IF(O38<=15,"ATENÇÃO","NO PRAZO")) -> ATENÇÃO | Q38: =WEEKNUM(Tabela1[[#This Row],[Prazo Entrega]],1) -> 31 | R38: c/ usinagem | S38: OK | T38: OK | U38: OK | V38: AG | W38: - | X38: AG | Y38: AG | Z38: AG | AA38: AG | AB38: =IF(L38="","AG. FUNDIDO",IF(U38="AG","AG. USINAGEM","EM USINAGEM")) -> EM USINAGEM | AD38: 27 | AE38: =Tabela1[[#This Row],[Plainar Facear]]+1 -> 28 | AF38: n/a | AG38: =Tabela1[[#This Row],[Serrar2]]+1 -> 29 | AH38: =Tabela1[[#This Row],[Encaixe / Furação]]+1 -> 30
A39: 2204 | B39: 1 | C39: 27516 | D39: 1 | E39: Raizen Energia S.A - Lagoa da Prata | F39: 1334017 | G39: 1 | H39: BAGACEIRA 78" | I39: 1 | J39: 46192 | K39: =WEEKNUM(Tabela1[[#This Row],[Prazo Fundido]]) -> 25 | L39: 46233 | M39: 46234 | O39: =Tabela1[[#This Row],[Prazo Entrega]]-TODAY() -> 15 | P39: =IF(O39<0,"ATRASADO",IF(O39<=15,"ATENÇÃO","NO PRAZO")) -> ATENÇÃO | Q39: =WEEKNUM(Tabela1[[#This Row],[Prazo Entrega]],1) -> 31 | R39: c/ usinagem | S39: OK | T39: OK | U39: AG | V39: AG | W39: - | X39: AG | Y39: AG | Z39: AG | AA39: AG | AB39: AG. USINAGEM | AD39: 27 | AE39: =Tabela1[[#This Row],[Plainar Facear]]+1 -> 28 | AF39: n/a | AG39: =Tabela1[[#This Row],[Serrar2]]+1 -> 29 | AH39: =Tabela1[[#This Row],[Encaixe / Furação]]+1 -> 30
A40: 2204 | B40: 2 | C40: 27516 | D40: 2 | E40: Raizen Energia S.A - Lagoa da Prata | F40: 1334018 | G40: 1 | H40: BAGACEIRA 78" | I40: 1 | J40: 46192 | K40: =WEEKNUM(Tabela1[[#This Row],[Prazo Fundido]]) -> 25 | L40: 46217 | M40: 46234 | O40: =Tabela1[[#This Row],[Prazo Entrega]]-TODAY() -> 15 | P40: =IF(O40<0,"ATRASADO",IF(O40<=15,"ATENÇÃO","NO PRAZO")) -> ATENÇÃO | Q40: =WEEKNUM(Tabela1[[#This Row],[Prazo Entrega]],1) -> 31 | R40: c/ usinagem | S40: OK | T40: OK | U40: AG | V40: AG | W40: - | X40: AG | Y40: AG | Z40: AG | AA40: AG | AB40: =IF(L40="","AG. FUNDIDO",IF(U40="AG","AG. USINAGEM","EM USINAGEM")) -> AG. USINAGEM | AD40: 28 | AE40: =Tabela1[[#This Row],[Plainar Facear]]+1 -> 29 | AF40: n/a | AG40: =Tabela1[[#This Row],[Serrar2]]+1 -> 30 | AH40: =Tabela1[[#This Row],[Encaixe / Furação]]+1 -> 31
...

Sheet PENTES
A1: PV | B1: Item | C1: O.S. | D1: Item2 | E1: Cliente | F1: Peça | G1: Seq. | H1: Descrição | I1: Qtde. | J1: Prazo Fundido | K1: Semana Fundido | L1: Pz Fundido Real | M1: Coluna1 | N1: Prazo Entrega | O1: Pz Entrega Real | P1: Desenho Previsão | Q1: Des. | R1: Dias Falta2 | S1: Indicador | T1: Semana Entrega | U1: CONDIÇÃO | V1: Status Usinagem | W1: Observação
A2: 2226 | B2: 7 | C2: 27527 | D2: 7 | E2: Aura Brazil | F2: 1495052 | G2: 1 | H2: PENTE CURVO - USINADO LISO | I2: 1 | J2: 46185 | K2: =WEEKNUM(Tabela3[[#This Row],[Prazo Fundido]]) -> 24 | L2: 46188 | N2: 46211 | P2: OK | Q2: OK | R2: OK | S2: =IF(R2<0,"ATRASADO",IF(R2<=15,"ATENÇÃO","NO PRAZO")) -> NO PRAZO | T2: =WEEKNUM(Tabela3[[#This Row],[Prazo Entrega]]) -> 28 | U2: c/ usinagem | V2: AG. COLETA
A3: 2226 | B3: 8 | C3: 27527 | D3: 8 | E3: Aura Brazil | F3: 1495052 | G3: 2 | H3: PENTE CURVO - USINADO LISO | I3: 1 | J3: 46185 | K3: =WEEKNUM(Tabela3[[#This Row],[Prazo Fundido]]) -> 24 | L3: 46188 | N3: 46211 | P3: OK | Q3: OK | R3: OK | S3: =IF(R3<0,"ATRASADO",IF(R3<=15,"ATENÇÃO","NO PRAZO")) -> NO PRAZO | T3: =WEEKNUM(Tabela3[[#This Row],[Prazo Entrega]]) -> 28 | U3: c/ usinagem | V3: AG. COLETA
A4: 2226 | B4: 9 | C4: 27527 | D4: 9 | E4: Aura Brazil | F4: 1495052 | G4: 3 | H4: PENTE CURVO - USINADO LISO | I4: 1 | J4: 46185 | K4: =WEEKNUM(Tabela3[[#This Row],[Prazo Fundido]]) -> 24 | L4: 46188 | N4: 46211 | P4: OK | Q4: OK | R4: OK | S4: =IF(R4<0,"ATRASADO",IF(R4<=15,"ATENÇÃO","NO PRAZO")) -> NO PRAZO | T4: =WEEKNUM(Tabela3[[#This Row],[Prazo Entrega]]) -> 28 | U4: c/ usinagem | V4: AG. COLETA
A5: 2226 | B5: 10 | C5: 27527 | D5: 10 | E5: Aura Brazil | F5: 1495052 | G5: 4 | H5: PENTE CURVO - USINADO LISO | I5: 1 | J5: 46185 | K5: =WEEKNUM(Tabela3[[#This Row],[Prazo Fundido]]) -> 24 | L5: 46188 | N5: 46211 | P5: OK | Q5: OK | R5: OK | S5: =IF(R5<0,"ATRASADO",IF(R5<=15,"ATENÇÃO","NO PRAZO")) -> NO PRAZO | T5: =WEEKNUM(Tabela3[[#This Row],[Prazo Entrega]]) -> 28 | U5: c/ usinagem | V5: AG. COLETA
A6: 2226 | B6: 11 | C6: 27527 | D6: 11 | E6: Aura Brazil | F6: 1495052 | G6: 5 | H6: PENTE CURVO - USINADO LISO | I6: 1 | J6: 46185 | K6: =WEEKNUM(Tabela3[[#This Row],[Prazo Fundido]]) -> 24 | L6: 46188 | N6: 46211 | P6: OK | Q6: OK | R6: OK | S6: =IF(R6<0,"ATRASADO",IF(R6<=15,"ATENÇÃO","NO PRAZO")) -> NO PRAZO | T6: =WEEKNUM(Tabela3[[#This Row],[Prazo Entrega]]) -> 28 | U6: c/ usinagem | V6: AG. COLETA
A7: 2226 | B7: 12 | C7: 27527 | D7: 12 | E7: Aura Brazil | F7: 1495052 | G7: 6 | H7: PENTE CURVO - USINADO LISO | I7: 1 | J7: 46185 | K7: =WEEKNUM(Tabela3[[#This Row],[Prazo Fundido]]) -> 24 | L7: 46188 | N7: 46211 | P7: OK | Q7: OK | R7: OK | S7: =IF(R7<0,"ATRASADO",IF(R7<=15,"ATENÇÃO","NO PRAZO")) -> NO PRAZO | T7: =WEEKNUM(Tabela3[[#This Row],[Prazo Entrega]]) -> 28 | U7: c/ usinagem | V7: AG. COLETA
A8: 2226 | B8: 13 | C8: 27527 | D8: 13 | E8: Aura Brazil | F8: 1495052 | G8: 7 | H8: PENTE CURVO - USINADO LISO | I8: 1 | J8: 46185 | K8: =WEEKNUM(Tabela3[[#This Row],[Prazo Fundido]]) -> 24 | L8: 46188 | N8: 46211 | P8: OK | Q8: OK | R8: OK | S8: =IF(R8<0,"ATRASADO",IF(R8<=15,"ATENÇÃO","NO PRAZO")) -> NO PRAZO | T8: =WEEKNUM(Tabela3[[#This Row],[Prazo Entrega]]) -> 28 | U8: c/ usinagem | V8: AG. COLETA
A9: 2226 | B9: 14 | C9: 27527 | D9: 14 | E9: Aura Brazil | F9: 1495052 | G9: 8 | H9: PENTE CURVO - USINADO LISO | I9: 1 | J9: 46185 | K9: =WEEKNUM(Tabela3[[#This Row],[Prazo Fundido]]) -> 24 | L9: 46188 | N9: 46211 | P9: OK | Q9: OK | R9: OK | S9: =IF(R9<0,"ATRASADO",IF(R9<=15,"ATENÇÃO","NO PRAZO")) -> NO PRAZO | T9: =WEEKNUM(Tabela3[[#This Row],[Prazo Entrega]]) -> 28 | U9: c/ usinagem | V9: AG. COLETA
A10: 2226 | B10: 15 | C10: 27527 | D10: 15 | E10: Aura Brazil | F10: 1495052 | G10: 9 | H10: PENTE CURVO - USINADO LISO | I10: 1 | J10: 46185 | K10: =WEEKNUM(Tabela3[[#This Row],[Prazo Fundido]]) -> 24 | L10: 46188 | N10: 46211 | P10: OK | Q10: OK | R10: OK | S10: =IF(R10<0,"ATRASADO",IF(R10<=15,"ATENÇÃO","NO PRAZO")) -> NO PRAZO | T10: =WEEKNUM(Tabela3[[#This Row],[Prazo Entrega]]) -> 28 | U10: c/ usinagem | V10: AG. COLETA
A11: 2226 | B11: 17 | C11: 27527 | D11: 17 | E11: Aura Brazil | F11: 1495054 | G11: 1 | H11: PENTE CURVO - USINADO LISO | I11: 1 | J11: 46185 | K11: =WEEKNUM(Tabela3[[#This Row],[Prazo Fundido]]) -> 24 | L11: 46188 | N11: 46211 | P11: OK | Q11: OK | R11: OK | S11: =IF(R11<0,"ATRASADO",IF(R11<=15,"ATENÇÃO","NO PRAZO")) -> NO PRAZO | T11: =WEEKNUM(Tabela3[[#This Row],[Prazo Entrega]]) -> 28 | U11: c/ usinagem | V11: AG. COLETA | W11: RNC 13867 - FUNDIU PENTE 66"
A12: 2226 | B12: 18 | C12: 27527 | D12: 18 | E12: Aura Brazil | F12: 1495054 | G12: 2 | H12: PENTE CURVO - USINADO LISO | I12: 1 | J12: 46185 | K12: =WEEKNUM(Tabela3[[#This Row],[Prazo Fundido]]) -> 24 | L12: 46188 | N12: 46211 | P12: OK | Q12: OK | R12: OK | S12: =IF(R12<0,"ATRASADO",IF(R12<=15,"ATENÇÃO","NO PRAZO")) -> NO PRAZO | T12: =WEEKNUM(Tabela3[[#This Row],[Prazo Entrega]]) -> 28 | U12: c/ usinagem | V12: AG. COLETA | W12: RNC 13868 - FUNDIU PENTE 66"
A13: 2226 | B13: 19 | C13: 27527 | D13: 19 | E13: Aura Brazil | F13: 1495054 | G13: 3 | H13: PENTE CURVO - USINADO LISO | I13: 1 | J13: 46185 | K13: =WEEKNUM(Tabela3[[#This Row],[Prazo Fundido]]) -> 24 | L13: 46188 | N13: 46211 | P13: OK | Q13: OK | R13: OK | S13: =IF(R13<0,"ATRASADO",IF(R13<=15,"ATENÇÃO","NO PRAZO")) -> NO PRAZO | T13: =WEEKNUM(Tabela3[[#This Row],[Prazo Entrega]]) -> 28 | U13: c/ usinagem | V13: AG. COLETA | W13: RNC 13869 - FUNDIU PENTE 66"
A14: 2227 | B14: 1 | C14: 27528 | D14: 1 | E14: MS Internacional | F14: 1454053 | G14: 1 | H14: PENTE INFERIOR CONVENCIONAL 84" | I14: 1 | J14: 46185 | K14: =WEEKNUM(Tabela3[[#This Row],[Prazo Fundido]]) -> 24 | L14: 46190 | N14: 46211 | P14: OK | Q14: OK | R14: OK | S14: =IF(R14<0,"ATRASADO",IF(R14<=15,"ATENÇÃO","NO PRAZO")) -> NO PRAZO | T14: =WEEKNUM(Tabela3[[#This Row],[Prazo Entrega]]) -> 28 | U14: c/ usinagem | V14: AG. COLETA
A15: 2227 | B15: 2 | C15: 27528 | D15: 2 | E15: MS Internacional | F15: 1454053 | G15: 2 | H15: PENTE INFERIOR CONVENCIONAL 84" | I15: 1 | J15: 46185 | K15: =WEEKNUM(Tabela3[[#This Row],[Prazo Fundido]]) -> 24 | L15: 46190 | N15: 46211 | P15: OK | Q15: OK | R15: OK | S15: =IF(R15<0,"ATRASADO",IF(R15<=15,"ATENÇÃO","NO PRAZO")) -> NO PRAZO | T15: =WEEKNUM(Tabela3[[#This Row],[Prazo Entrega]]) -> 28 | U15: c/ usinagem | V15: AG. COLETA
A16: 2227 | B16: 3 | C16: 27528 | D16: 3 | E16: MS Internacional | F16: 1454053 | G16: 3 | H16: PENTE INFERIOR CONVENCIONAL 84" | I16: 1 | J16: 46185 | K16: =WEEKNUM(Tabela3[[#This Row],[Prazo Fundido]]) -> 24 | L16: 46190 | N16: 46211 | P16: OK | Q16: OK | R16: OK | S16: =IF(R16<0,"ATRASADO",IF(R16<=15,"ATENÇÃO","NO PRAZO")) -> NO PRAZO | T16: =WEEKNUM(Tabela3[[#This Row],[Prazo Entrega]]) -> 28 | U16: c/ usinagem | V16: AG. COLETA
A17: 2227 | B17: 4 | C17: 27528 | D17: 4 | E17: MS Internacional | F17: 1454053 | G17: 4 | H17: PENTE INFERIOR CONVENCIONAL 84" | I17: 1 | J17: 46185 | K17: =WEEKNUM(Tabela3[[#This Row],[Prazo Fundido]]) -> 24 | L17: 46190 | N17: 46211 | P17: OK | Q17: OK | R17: OK | S17: =IF(R17<0,"ATRASADO",IF(R17<=15,"ATENÇÃO","NO PRAZO")) -> NO PRAZO | T17: =WEEKNUM(Tabela3[[#This Row],[Prazo Entrega]]) -> 28 | U17: c/ usinagem | V17: AG. COLETA
A18: 2227 | B18: 5 | C18: 27528 | D18: 5 | E18: MS Internacional | F18: 1454054 | G18: 1 | H18: PENTE SUPERIOR CONVENCIONAL 84" | I18: 1 | J18: 46185 | K18: =WEEKNUM(Tabela3[[#This Row],[Prazo Fundido]]) -> 24 | L18: 46188 | N18: 46211 | P18: OK | Q18: OK | R18: OK | S18: =IF(R18<0,"ATRASADO",IF(R18<=15,"ATENÇÃO","NO PRAZO")) -> NO PRAZO | T18: =WEEKNUM(Tabela3[[#This Row],[Prazo Entrega]]) -> 28 | U18: c/ usinagem | V18: AG. COLETA
A19: 2227 | B19: 6 | C19: 27528 | D19: 6 | E19: MS Internacional | F19: 1454054 | G19: 2 | H19: PENTE SUPERIOR CONVENCIONAL 84" | I19: 1 | J19: 46185 | K19: =WEEKNUM(Tabela3[[#This Row],[Prazo Fundido]]) -> 24 | L19: 46188 | N19: 46211 | P19: OK | Q19: OK | R19: OK | S19: =IF(R19<0,"ATRASADO",IF(R19<=15,"ATENÇÃO","NO PRAZO")) -> NO PRAZO | T19: =WEEKNUM(Tabela3[[#This Row],[Prazo Entrega]]) -> 28 | U19: c/ usinagem | V19: AG. COLETA
A20: 2227 | B20: 7 | C20: 27528 | D20: 7 | E20: MS Internacional | F20: 1454054 | G20: 3 | H20: PENTE SUPERIOR CONVENCIONAL 84" | I20: 1 | J20: 46185 | K20: =WEEKNUM(Tabela3[[#This Row],[Prazo Fundido]]) -> 24 | L20: 46188 | N20: 46211 | P20: OK | Q20: OK | R20: OK | S20: =IF(R20<0,"ATRASADO",IF(R20<=15,"ATENÇÃO","NO PRAZO")) -> NO PRAZO | T20: =WEEKNUM(Tabela3[[#This Row],[Prazo Entrega]]) -> 28 | U20: c/ usinagem | V20: AG. COLETA
A21: 2227 | B21: 8 | C21: 27528 | D21: 8 | E21: MS Internacional | F21: 1454053 | G21: 5 | H21: PENTE INFERIOR CONVENCIONAL 84" | I21: 1 | J21: 46185 | K21: =WEEKNUM(Tabela3[[#This Row],[Prazo Fundido]]) -> 24 | L21: 46190 | N21: 46211 | P21: OK | Q21: OK | R21: OK | S21: =IF(R21<0,"ATRASADO",IF(R21<=15,"ATENÇÃO","NO PRAZO")) -> NO PRAZO | T21: =WEEKNUM(Tabela3[[#This Row],[Prazo Entrega]]) -> 28 | U21: c/ usinagem | V21: AG. COLETA
A22: 2227 | B22: 9 | C22: 27528 | D22: 9 | E22: MS Internacional | F22: 1454053 | G22: 6 | H22: PENTE INFERIOR CONVENCIONAL 84" | I22: 1 | J22: 46185 | K22: =WEEKNUM(Tabela3[[#This Row],[Prazo Fundido]]) -> 24 | L22: 46190 | N22: 46211 | P22: OK | Q22: OK | R22: OK | S22: =IF(R22<0,"ATRASADO",IF(R22<=15,"ATENÇÃO","NO PRAZO")) -> NO PRAZO | T22: =WEEKNUM(Tabela3[[#This Row],[Prazo Entrega]]) -> 28 | U22: c/ usinagem | V22: AG. COLETA
A23: 2227 | B23: 10 | C23: 27528 | D23: 10 | E23: MS Internacional | F23: 1454053 | G23: 7 | H23: PENTE INFERIOR CONVENCIONAL 84" | I23: 1 | J23: 46185 | K23: =WEEKNUM(Tabela3[[#This Row],[Prazo Fundido]]) -> 24 | L23: 46190 | N23: 46211 | P23: OK | Q23: OK | R23: OK | S23: =IF(R23<0,"ATRASADO",IF(R23<=15,"ATENÇÃO","NO PRAZO")) -> NO PRAZO | T23: =WEEKNUM(Tabela3[[#This Row],[Prazo Entrega]]) -> 28 | U23: c/ usinagem | V23: AG. COLETA
A24: 2227 | B24: 11 | C24: 27528 | D24: 11 | E24: MS Internacional | F24: 1454053 | G24: 8 | H24: PENTE INFERIOR CONVENCIONAL 84" | I24: 1 | J24: 46185 | K24: =WEEKNUM(Tabela3[[#This Row],[Prazo Fundido]]) -> 24 | L24: 46190 | N24: 46211 | P24: OK | Q24: OK | R24: OK | S24: =IF(R24<0,"ATRASADO",IF(R24<=15,"ATENÇÃO","NO PRAZO")) -> NO PRAZO | T24: =WEEKNUM(Tabela3[[#This Row],[Prazo Entrega]]) -> 28 | U24: c/ usinagem | V24: AG. COLETA
A25: 2227 | B25: 12 | C25: 27528 | D25: 12 | E25: MS Internacional | F25: 1454054 | G25: 4 | H25: PENTE SUPERIOR CONVENCIONAL 84" | I25: 1 | J25: 46185 | K25: =WEEKNUM(Tabela3[[#This Row],[Prazo Fundido]]) -> 24 | L25: 46188 | N25: 46211 | P25: OK | Q25: OK | R25: OK | S25: =IF(R25<0,"ATRASADO",IF(R25<=15,"ATENÇÃO","NO PRAZO")) -> NO PRAZO | T25: =WEEKNUM(Tabela3[[#This Row],[Prazo Entrega]]) -> 28 | U25: c/ usinagem | V25: AG. COLETA
A26: 2227 | B26: 13 | C26: 27528 | D26: 13 | E26: MS Internacional | F26: 1454054 | G26: 5 | H26: PENTE SUPERIOR CONVENCIONAL 84" | I26: 1 | J26: 46185 | K26: =WEEKNUM(Tabela3[[#This Row],[Prazo Fundido]]) -> 24 | L26: 46188 | N26: 46211 | P26: OK | Q26: OK | R26: OK | S26: =IF(R26<0,"ATRASADO",IF(R26<=15,"ATENÇÃO","NO PRAZO")) -> NO PRAZO | T26: =WEEKNUM(Tabela3[[#This Row],[Prazo Entrega]]) -> 28 | U26: c/ usinagem | V26: AG. COLETA
A27: 2227 | B27: 21 | C27: CHAPA | D27: - | E27: MS Internacional | F27: CHAPA | G27: - | H27: PENTE SUPERIOR EM CHAPA RETO 82" | I27: 1 | J27: 46183 | K27: =WEEKNUM(Tabela3[[#This Row],[Prazo Fundido]]) -> 24 | L27: 46183 | N27: 46211 | P27: OK | Q27: OK | R27: OK | S27: =IF(R27<0,"ATRASADO",IF(R27<=15,"ATENÇÃO","NO PRAZO")) -> NO PRAZO | T27: =WEEKNUM(Tabela3[[#This Row],[Prazo Entrega]]) -> 28 | U27: c/ usinagem | V27: AG. COLETA
A28: 2227 | B28: 22 | C28: CHAPA | D28: - | E28: MS Internacional | F28: CHAPA | G28: - | H28: PENTE SUPERIOR EM CHAPA RETO 82" | I28: 1 | J28: 46183 | K28: =WEEKNUM(Tabela3[[#This Row],[Prazo Fundido]]) -> 24 | L28: 46183 | N28: 46211 | P28: OK | Q28: OK | R28: OK | S28: =IF(R28<0,"ATRASADO",IF(R28<=15,"ATENÇÃO","NO PRAZO")) -> NO PRAZO | T28: =WEEKNUM(Tabela3[[#This Row],[Prazo Entrega]]) -> 28 | U28: c/ usinagem | V28: AG. COLETA
A29: 2227 | B29: 23 | C29: CHAPA | D29: - | E29: MS Internacional | F29: CHAPA | G29: - | H29: PENTE SUPERIOR EM CHAPA RETO 82" | I29: 1 | J29: 46183 | K29: =WEEKNUM(Tabela3[[#This Row],[Prazo Fundido]]) -> 24 | L29: 46183 | N29: 46211 | P29: OK | Q29: OK | R29: OK | S29: =IF(R29<0,"ATRASADO",IF(R29<=15,"ATENÇÃO","NO PRAZO")) -> NO PRAZO | T29: =WEEKNUM(Tabela3[[#This Row],[Prazo Entrega]]) -> 28 | U29: c/ usinagem | V29: AG. COLETA
A30: 2227 | B30: 24 | C30: CHAPA | D30: - | E30: MS Internacional | F30: CHAPA | G30: - | H30: PENTE SUPERIOR EM CHAPA RETO 82" | I30: 1 | J30: 46183 | K30: =WEEKNUM(Tabela3[[#This Row],[Prazo Fundido]]) -> 24 | L30: 46183 | N30: 46211 | P30: OK | Q30: OK | R30: OK | S30: =IF(R30<0,"ATRASADO",IF(R30<=15,"ATENÇÃO","NO PRAZO")) -> NO PRAZO | T30: =WEEKNUM(Tabela3[[#This Row],[Prazo Entrega]]) -> 28 | U30: c/ usinagem | V30: AG. COLETA
A31: 2227 | B31: 25 | C31: CHAPA | D31: - | E31: MS Internacional | F31: CHAPA | G31: - | H31: PENTE SUPERIOR EM CHAPA RETO 82" | I31: 1 | J31: 46183 | K31: =WEEKNUM(Tabela3[[#This Row],[Prazo Fundido]]) -> 24 | L31: 46183 | N31: 46211 | P31: OK | Q31: OK | R31: OK | S31: =IF(R31<0,"ATRASADO",IF(R31<=15,"ATENÇÃO","NO PRAZO")) -> NO PRAZO | T31: =WEEKNUM(Tabela3[[#This Row],[Prazo Entrega]]) -> 28 | U31: c/ usinagem | V31: AG. COLETA
A32: 2227 | B32: 26 | C32: CHAPA | D32: - | E32: MS Internacional | F32: CHAPA | G32: - | H32: PENTE SUPERIOR EM CHAPA RETO 82" | I32: 1 | J32: 46183 | K32: =WEEKNUM(Tabela3[[#This Row],[Prazo Fundido]]) -> 24 | L32: 46183 | N32: 46211 | P32: OK | Q32: OK | R32: OK | S32: =IF(R32<0,"ATRASADO",IF(R32<=15,"ATENÇÃO","NO PRAZO")) -> NO PRAZO | T32: =WEEKNUM(Tabela3[[#This Row],[Prazo Entrega]]) -> 28 | U32: c/ usinagem | V32: AG. COLETA
A33: 1951 | B33: 9 | C33: 27276 | D33: - | E33: Cofco Potirendaba | F33: 1202015 | G33: - | H33: PENTE SUPERIOR CURVO 78" | I33: 1 | J33: 46190 | K33: =WEEKNUM(Tabela3[[#This Row],[Prazo Fundido]]) -> 25 | L33: 46190 | N33: 46233 | P33: OK | Q33: OK | R33: =Tabela3[[#This Row],[Prazo Entrega]]-TODAY() -> 14 | S33: =IF(R33<0,"ATRASADO",IF(R33<=15,"ATENÇÃO","NO PRAZO")) -> ATENÇÃO | T33: =WEEKNUM(Tabela3[[#This Row],[Prazo Entrega]]) -> 31 | U33: c/ usinagem | V33: EM INSPEÇÃO
A34: 1951 | B34: 10 | C34: 27276 | D34: - | E34: Cofco Potirendaba | F34: 1202015 | G34: - | H34: PENTE SUPERIOR CURVO 78" | I34: 1 | J34: 46190 | K34: =WEEKNUM(Tabela3[[#This Row],[Prazo Fundido]]) -> 25 | L34: 46190 | N34: 46233 | P34: OK | Q34: OK | R34: =Tabela3[[#This Row],[Prazo Entrega]]-TODAY() -> 14 | S34: =IF(R34<0,"ATRASADO",IF(R34<=15,"ATENÇÃO","NO PRAZO")) -> ATENÇÃO | T34: =WEEKNUM(Tabela3[[#This Row],[Prazo Entrega]]) -> 31 | U34: c/ usinagem | V34: EM INSPEÇÃO
A35: 1951 | B35: 11 | C35: 27276 | D35: - | E35: Cofco Potirendaba | F35: 1202015 | G35: - | H35: PENTE SUPERIOR CURVO 78" | I35: 1 | J35: 46190 | K35: =WEEKNUM(Tabela3[[#This Row],[Prazo Fundido]]) -> 25 | L35: 46190 | N35: 46233 | P35: OK | Q35: OK | R35: =Tabela3[[#This Row],[Prazo Entrega]]-TODAY() -> 14 | S35: =IF(R35<0,"ATRASADO",IF(R35<=15,"ATENÇÃO","NO PRAZO")) -> ATENÇÃO | T35: =WEEKNUM(Tabela3[[#This Row],[Prazo Entrega]]) -> 31 | U35: c/ usinagem | V35: EM INSPEÇÃO
A36: 1951 | B36: 12 | C36: 27276 | D36: - | E36: Cofco Potirendaba | F36: 1202015 | G36: - | H36: PENTE SUPERIOR CURVO 78" | I36: 1 | J36: 46190 | K36: =WEEKNUM(Tabela3[[#This Row],[Prazo Fundido]]) -> 25 | L36: 46190 | N36: 46233 | P36: OK | Q36: OK | R36: =Tabela3[[#This Row],[Prazo Entrega]]-TODAY() -> 14 | S36: =IF(R36<0,"ATRASADO",IF(R36<=15,"ATENÇÃO","NO PRAZO")) -> ATENÇÃO | T36: =WEEKNUM(Tabela3[[#This Row],[Prazo Entrega]]) -> 31 | U36: c/ usinagem | V36: EM INSPEÇÃO
A37: 1951 | B37: 13 | C37: 27276 | D37: - | E37: Cofco Potirendaba | F37: 1202015 | G37: - | H37: PENTE SUPERIOR CURVO 78" | I37: 1 | J37: 46190 | K37: =WEEKNUM(Tabela3[[#This Row],[Prazo Fundido]]) -> 25 | L37: 46190 | N37: 46233 | P37: OK | Q37: OK | R37: =Tabela3[[#This Row],[Prazo Entrega]]-TODAY() -> 14 | S37: =IF(R37<0,"ATRASADO",IF(R37<=15,"ATENÇÃO","NO PRAZO")) -> ATENÇÃO | T37: =WEEKNUM(Tabela3[[#This Row],[Prazo Entrega]]) -> 31 | U37: c/ usinagem | V37: EM INSPEÇÃO
A38: 1031 | B38: 3 | C38: 27609 | D38: 3 | E38: Água Bonita | F38: - | G38: - | H38: PENTE SUPERIOR CONVENCIONAL 84" | I38: 1 | J38: 46226 | K38: =WEEKNUM(Tabela3[[#This Row],[Prazo Fundido]]) -> 30 | N38: 46266 | P38: OK | Q38: OK | R38: =Tabela3[[#This Row],[Prazo Entrega]]-TODAY() -> 47 | S38: =IF(R38<0,"ATRASADO",IF(R38<=15,"ATENÇÃO","NO PRAZO")) -> NO PRAZO | T38: =WEEKNUM(Tabela3[[#This Row],[Prazo Entrega]]) -> 36 | U38: c/ usinagem | V38: AG. FUNDIDO
A39: 1031 | B39: 4 | C39: 27609 | D39: 4 | E39: Água Bonita | F39: - | G39: - | H39: PENTE SUPERIOR CONVENCIONAL 84" | I39: 1 | J39: 46226 | K39: =WEEKNUM(Tabela3[[#This Row],[Prazo Fundido]]) -> 30 | N39: 46266 | P39: OK | Q39: OK | R39: =Tabela3[[#This Row],[Prazo Entrega]]-TODAY() -> 47 | S39: =IF(R39<0,"ATRASADO",IF(R39<=15,"ATENÇÃO","NO PRAZO")) -> NO PRAZO | T39: =WEEKNUM(Tabela3[[#This Row],[Prazo Entrega]]) -> 36 | U39: c/ usinagem | V39: AG. FUNDIDO
A40: 1031 | B40: 5 | C40: 27609 | D40: 5 | E40: Água Bonita | F40: - | G40: - | H40: PENTE SUPERIOR CONVENCIONAL 84" | I40: 1 | J40: 46226 | K40: =WEEKNUM(Tabela3[[#This Row],[Prazo Fundido]]) -> 30 | N40: 46266 | P40: OK | Q40: OK | R40: =Tabela3[[#This Row],[Prazo Entrega]]-TODAY() -> 47 | S40: =IF(R40<0,"ATRASADO",IF(R40<=15,"ATENÇÃO","NO PRAZO")) -> NO PRAZO | T40: =WEEKNUM(Tabela3[[#This Row],[Prazo Entrega]]) -> 36 | U40: c/ usinagem | V40: AG. FUNDIDO
...

Sheet RODETES NOVOS
A1: PV | B1: Item | C1: OS | D1: Item2 | E1: Cliente | F1: Cod. | G1: Seq. | H1: Descrição | I1: Qtd. | J1: Data Prev. Fundido | K1: Data Real Fundido | L1: Data Prev. Entrega | M1: Data Real Entrega | N1: Falta Dias | O1: Indicador | P1: Condição | Q1: Desenho Previsão | R1: Des. | S1: Desb. | T1: T.T. | U1: Us. Final | V1: Fundo D. | W1: Acabam. | X1: Liberação | Y1: Status Usinagem | Z1: Observação
A2: 2233 | B2: 1 | C2: 27543 | D2: 1 | E2: Coprodria | F2: 250039 | G2: 1 | H2: RODETE MDA Z15 Ø1320MM 78" | I2: 1 | J2: 46209 | L2: 46269 | N2: =Tabela13[[#This Row],[Data Prev. Entrega]]-TODAY() -> 50 | O2: =IF(N2<0,"ATRASADO",IF(N2<=15,"ATENÇÃO","NO PRAZO")) -> NO PRAZO | P2: c/ usinagem | Q2: OK | R2: OK | S2: AG | T2: AG | U2: AG | V2: AG | W2: AG | X2: AG | Y2: =IF(K2="","AG. FUNDIDO",IF(X2="OK","LIBERADA","EM USINAGEM")) -> AG. FUNDIDO
A3: 2233 | B3: 2 | C3: 27543 | D3: 2 | E3: Coprodria | F3: 250040 | G3: 1 | H3: RODETE MDA Z15 Ø1280MM 78" | I3: 1 | J3: 46209 | L3: 46269 | N3: =Tabela13[[#This Row],[Data Prev. Entrega]]-TODAY() -> 50 | O3: =IF(N3<0,"ATRASADO",IF(N3<=15,"ATENÇÃO","NO PRAZO")) -> NO PRAZO | P3: c/ usinagem | Q3: OK | R3: OK | S3: AG | T3: AG | U3: AG | V3: AG | W3: AG | X3: AG | Y3: =IF(K3="","AG. FUNDIDO",IF(X3="OK","LIBERADA","EM USINAGEM")) -> AG. FUNDIDO
A4: 2284 | B4: 1 | C4: 27563 | D4: 1 | E4: Simisa | F4: 212076 | G4: 1 | H4: RODETE MDA Z15 (BRUTO) | I4: 1 | J4: 46239 | L4: 46239 | N4: =Tabela13[[#This Row],[Data Prev. Entrega]]-TODAY() -> 20 | O4: =IF(N4<0,"ATRASADO",IF(N4<=15,"ATENÇÃO","NO PRAZO")) -> NO PRAZO | P4: Bruto | Q4: - | R4: - | S4: - | T4: - | U4: - | V4: - | W4: - | X4: - | Y4: =IF(K4="","AG. FUNDIDO",IF(X4="OK","LIBERADA","EM USINAGEM")) -> AG. FUNDIDO
A5: 2284 | B5: 2 | C5: 27563 | D5: 2 | E5: Simisa | F5: 212076 | G5: 2 | H5: RODETE MDA Z15 (BRUTO) | I5: 1 | J5: 46239 | L5: 46239 | N5: =Tabela13[[#This Row],[Data Prev. Entrega]]-TODAY() -> 20 | O5: =IF(N5<0,"ATRASADO",IF(N5<=15,"ATENÇÃO","NO PRAZO")) -> NO PRAZO | P5: Bruto | Q5: - | R5: - | S5: - | T5: - | U5: - | V5: - | W5: - | X5: - | Y5: =IF(K5="","AG. FUNDIDO",IF(X5="OK","LIBERADA","EM USINAGEM")) -> AG. FUNDIDO
A6: 2284 | B6: 3 | C6: 27563 | D6: 3 | E6: Simisa | F6: 212076 | G6: 3 | H6: RODETE MDA Z15 (BRUTO) | I6: 1 | J6: 46239 | L6: 46239 | N6: =Tabela13[[#This Row],[Data Prev. Entrega]]-TODAY() -> 20 | O6: =IF(N6<0,"ATRASADO",IF(N6<=15,"ATENÇÃO","NO PRAZO")) -> NO PRAZO | P6: Bruto | Q6: - | R6: - | S6: - | T6: - | U6: - | V6: - | W6: - | X6: - | Y6: =IF(K6="","AG. FUNDIDO",IF(X6="OK","LIBERADA","EM USINAGEM")) -> AG. FUNDIDO
A7: 2284 | B7: 4 | C7: 27563 | D7: 4 | E7: Simisa | F7: 212077 | G7: 1 | H7: RODETE MDA Z15 (BRUTO) | I7: 1 | J7: 46295 | L7: 46295 | N7: =Tabela13[[#This Row],[Data Prev. Entrega]]-TODAY() -> 76 | O7: =IF(N7<0,"ATRASADO",IF(N7<=15,"ATENÇÃO","NO PRAZO")) -> NO PRAZO | P7: Bruto | Q7: - | R7: - | S7: - | T7: - | U7: - | V7: - | W7: - | X7: - | Y7: =IF(K7="","AG. FUNDIDO",IF(X7="OK","LIBERADA","EM USINAGEM")) -> AG. FUNDIDO
A8: 2284 | B8: 5 | C8: 27563 | D8: 5 | E8: Simisa | F8: 212078 | G8: 1 | H8: RODETE MDA Z15 (BRUTO) | I8: 1 | J8: 46239 | L8: 46239 | N8: =Tabela13[[#This Row],[Data Prev. Entrega]]-TODAY() -> 20 | O8: =IF(N8<0,"ATRASADO",IF(N8<=15,"ATENÇÃO","NO PRAZO")) -> NO PRAZO | P8: Bruto | Q8: - | R8: - | S8: - | T8: - | U8: - | V8: - | W8: - | X8: - | Y8: =IF(K8="","AG. FUNDIDO",IF(X8="OK","LIBERADA","EM USINAGEM")) -> AG. FUNDIDO
A9: 2284 | B9: 6 | C9: 27563 | D9: 6 | E9: Simisa | F9: 212079 | G9: 1 | H9: RODETE MDA Z15 (BRUTO) | I9: 1 | J9: 46266 | L9: 46266 | N9: =Tabela13[[#This Row],[Data Prev. Entrega]]-TODAY() -> 47 | O9: =IF(N9<0,"ATRASADO",IF(N9<=15,"ATENÇÃO","NO PRAZO")) -> NO PRAZO | P9: Bruto | Q9: - | R9: - | S9: - | T9: - | U9: - | V9: - | W9: - | X9: - | Y9: =IF(K9="","AG. FUNDIDO",IF(X9="OK","LIBERADA","EM USINAGEM")) -> AG. FUNDIDO
A10: 2284 | B10: 7 | C10: 27563 | D10: 7 | E10: Simisa | F10: 212078 | G10: 2 | H10: RODETE MDA Z15 (BRUTO) | I10: 1 | J10: 46266 | L10: 46266 | N10: =Tabela13[[#This Row],[Data Prev. Entrega]]-TODAY() -> 47 | O10: =IF(N10<0,"ATRASADO",IF(N10<=15,"ATENÇÃO","NO PRAZO")) -> NO PRAZO | P10: Bruto | Q10: - | R10: - | S10: - | T10: - | U10: - | V10: - | W10: - | X10: - | Y10: =IF(K10="","AG. FUNDIDO",IF(X10="OK","LIBERADA","EM USINAGEM")) -> AG. FUNDIDO
A11: 2284 | B11: 8 | C11: 27563 | D11: 8 | E11: Simisa | F11: 212080 | G11: 1 | H11: RODETE MDA Z15 (BRUTO) | I11: 1 | J11: 46266 | L11: 46266 | N11: =Tabela13[[#This Row],[Data Prev. Entrega]]-TODAY() -> 47 | O11: =IF(N11<0,"ATRASADO",IF(N11<=15,"ATENÇÃO","NO PRAZO")) -> NO PRAZO | P11: Bruto | Q11: - | R11: - | S11: - | T11: - | U11: - | V11: - | W11: - | X11: - | Y11: =IF(K11="","AG. FUNDIDO",IF(X11="OK","LIBERADA","EM USINAGEM")) -> AG. FUNDIDO
A12: 2284 | B12: 9 | C12: 27563 | D12: 9 | E12: Simisa | F12: 212080 | G12: 2 | H12: RODETE MDA Z15 (BRUTO) | I12: 1 | J12: 46266 | L12: 46266 | N12: =Tabela13[[#This Row],[Data Prev. Entrega]]-TODAY() -> 47 | O12: =IF(N12<0,"ATRASADO",IF(N12<=15,"ATENÇÃO","NO PRAZO")) -> NO PRAZO | P12: Bruto | Q12: - | R12: - | S12: - | T12: - | U12: - | V12: - | W12: - | X12: - | Y12: =IF(K12="","AG. FUNDIDO",IF(X12="OK","LIBERADA","EM USINAGEM")) -> AG. FUNDIDO
A13: 2284 | B13: 10 | C13: 27563 | D13: 10 | E13: Simisa | F13: 212080 | G13: 3 | H13: RODETE MDA Z15 (BRUTO) | I13: 1 | J13: 46266 | L13: 46266 | N13: =Tabela13[[#This Row],[Data Prev. Entrega]]-TODAY() -> 47 | O13: =IF(N13<0,"ATRASADO",IF(N13<=15,"ATENÇÃO","NO PRAZO")) -> NO PRAZO | P13: Bruto | Q13: - | R13: - | S13: - | T13: - | U13: - | V13: - | W13: - | X13: - | Y13: =IF(K13="","AG. FUNDIDO",IF(X13="OK","LIBERADA","EM USINAGEM")) -> AG. FUNDIDO
... A16: 2284 | B16: 13 | C16: 27563 | D16: 13 | E16: Simisa | F16: 212080 | G16: 6 | H16: RODETE MDA Z15 (BRUTO) | I16: 1 | J16: 46295 | L16: 46295 | N16: =Tabela13[[#This Row],[Data Prev. Entrega]]-TODAY() -> 76 | O16: =IF(N16<0,"ATRASADO",IF(N16<=15,"ATENÇÃO","NO PRAZO")) -> NO PRAZO | P16: Bruto | Q16: - | R16: - | S16: - | T16: - | U16: - | V16: - | W16: - | X16: - | Y16: =IF(K16="","AG. FUNDIDO",IF(X16="OK","LIBERADA","EM USINAGEM")) -> AG. FUNDIDO
A17: 2320 | B17: 1 | C17: 27607 | D17: 1 | E17: São João Araras | F17: 1127009 | G17: 1 | H17: RODETE PRESSÃO Z20 - 78" | I17: 1 | J17: 46249 | L17: 46280 | N17: =Tabela13[[#This Row],[Data Prev. Entrega]]-TODAY() -> 61 | O17: =IF(N17<0,"ATRASADO",IF(N17<=15,"ATENÇÃO","NO PRAZO")) -> NO PRAZO | P17: c/ usinagem | Q17: =Tabela13[[#This Row],[Data Prev. Fundido]]-10 -> 46239 | R17: AG | S17: AG | T17: AG | U17: AG | V17: AG | W17: AG | X17: AG | Y17: =IF(K17="","AG. FUNDIDO",IF(X17="OK","LIBERADA","EM USINAGEM")) -> AG. FUNDIDO
A18: 2320 | B18: 2 | C18: 27607 | D18: 2 | E18: São João Araras | F18: 1127003 | G18: 11 | H18: RODETE PRESSÃO Z15 - 84" | I18: 1 | J18: 46249 | L18: 46280 | N18: =Tabela13[[#This Row],[Data Prev. Entrega]]-TODAY() -> 61 | O18: =IF(N18<0,"ATRASADO",IF(N18<=15,"ATENÇÃO","NO PRAZO")) -> NO PRAZO | P18: c/ usinagem | Q18: =Tabela13[[#This Row],[Data Prev. Fundido]]-10 -> 46239 | R18: AG | S18: AG | T18: AG | U18: AG | V18: AG | W18: AG | X18: AG | Y18: =IF(K18="","AG. FUNDIDO",IF(X18="OK","LIBERADA","EM USINAGEM")) -> AG. FUNDIDO
A19: 2320 | B19: 3 | C19: 27607 | D19: 3 | E19: São João Araras | F19: 1127003 | G19: 12 | H19: RODETE MOENDA Z15 - 84" | I19: 1 | J19: 46249 | L19: 46280 | N19: =Tabela13[[#This Row],[Data Prev. Entrega]]-TODAY() -> 61 | O19: =IF(N19<0,"ATRASADO",IF(N19<=15,"ATENÇÃO","NO PRAZO")) -> NO PRAZO | P19: c/ usinagem | Q19: =Tabela13[[#This Row],[Data Prev. Fundido]]-10 -> 46239 | R19: AG | S19: AG | T19: AG | U19: AG | V19: AG | W19: AG | X19: AG | Y19: =IF(K19="","AG. FUNDIDO",IF(X19="OK","LIBERADA","EM USINAGEM")) -> AG. FUNDIDO
A20: 2320 | B20: 4 | C20: 27607 | D20: 4 | E20: São João Araras | F20: 1127003 | G20: 13 | H20: RODETE MOENDA Z15 - 84" | I20: 1 | J20: 46249 | L20: 46280 | N20: =Tabela13[[#This Row],[Data Prev. Entrega]]-TODAY() -> 61 | O20: =IF(N20<0,"ATRASADO",IF(N20<=15,"ATENÇÃO","NO PRAZO")) -> NO PRAZO | P20: c/ usinagem | Q20: =Tabela13[[#This Row],[Data Prev. Fundido]]-10 -> 46239 | R20: AG | S20: AG | T20: AG | U20: AG | V20: AG | W20: AG | X20: AG | Y20: =IF(K20="","AG. FUNDIDO",IF(X20="OK","LIBERADA","EM USINAGEM")) -> AG. FUNDIDO
A21: 2320 | B21: 5 | C21: 27607 | D21: 5 | E21: São João Araras | F21: 1127005 | G21: 12 | H21: RODETE MOENDA Z15 - 84" | I21: 1 | J21: 46249 | L21: 46280 | N21: =Tabela13[[#This Row],[Data Prev. Entrega]]-TODAY() -> 61 | O21: =IF(N21<0,"ATRASADO",IF(N21<=15,"ATENÇÃO","NO PRAZO")) -> NO PRAZO | P21: c/ usinagem | Q21: =Tabela13[[#This Row],[Data Prev. Fundido]]-10 -> 46239 | R21: AG | S21: AG | T21: AG | U21: AG | V21: AG | W21: AG | X21: AG | Y21: =IF(K21="","AG. FUNDIDO",IF(X21="OK","LIBERADA","EM USINAGEM")) -> AG. FUNDIDO
A22: 2320 | B22: 6 | C22: 27607 | D22: 6 | E22: São João Araras | F22: 1127005 | G22: 13 | H22: RODETE MOENDA Z15 - 84" | I22: 1 | J22: 46249 | L22: 46280 | N22: =Tabela13[[#This Row],[Data Prev. Entrega]]-TODAY() -> 61 | O22: =IF(N22<0,"ATRASADO",IF(N22<=15,"ATENÇÃO","NO PRAZO")) -> NO PRAZO | P22: c/ usinagem | Q22: =Tabela13[[#This Row],[Data Prev. Fundido]]-10 -> 46239 | R22: AG | S22: AG | T22: AG | U22: AG | V22: AG | W22: AG | X22: AG | Y22: =IF(K22="","AG. FUNDIDO",IF(X22="OK","LIBERADA","EM USINAGEM")) -> AG. FUNDIDO
A23: 2320 | B23: 7 | C23: 27607 | D23: 7 | E23: São João Araras | F23: 1127005 | G23: 14 | H23: RODETE MOENDA Z15 - 84" | I23: 1 | J23: 46249 | L23: 46280 | N23: =Tabela13[[#This Row],[Data Prev. Entrega]]-TODAY() -> 61 | O23: =IF(N23<0,"ATRASADO",IF(N23<=15,"ATENÇÃO","NO PRAZO")) -> NO PRAZO | P23: c/ usinagem | Q23: =Tabela13[[#This Row],[Data Prev. Fundido]]-10 -> 46239 | R23: AG | S23: AG | T23: AG | U23: AG | V23: AG | W23: AG | X23: AG | Y23: =IF(K23="","AG. FUNDIDO",IF(X23="OK","LIBERADA","EM USINAGEM")) -> AG. FUNDIDO
A24: 2320 | B24: 8 | C24: 27607 | D24: 8 | E24: São João Araras | F24: 1127016 | G24: 1 | H24: RODETE PRESSÃO Z20 - 84" | I24: 1 | J24: 46249 | L24: 46280 | N24: =Tabela13[[#This Row],[Data Prev. Entrega]]-TODAY() -> 61 | O24: =IF(N24<0,"ATRASADO",IF(N24<=15,"ATENÇÃO","NO PRAZO")) -> NO PRAZO | P24: c/ usinagem | Q24: =Tabela13[[#This Row],[Data Prev. Fundido]]-10 -> 46239 | R24: AG | S24: AG | T24: AG | U24: AG | V24: AG | W24: AG | X24: AG | Y24: =IF(K24="","AG. FUNDIDO",IF(X24="OK","LIBERADA","EM USINAGEM")) -> AG. FUNDIDO
A25: 2320 | B25: 9 | C25: 27607 | D25: 9 | E25: São João Araras | F25: 1127017 | G25: 1 | H25: RODETE PRESSÃO Z15 - 84" | I25: 1 | J25: 46249 | L25: 46280 | N25: =Tabela13[[#This Row],[Data Prev. Entrega]]-TODAY() -> 61 | O25: =IF(N25<0,"ATRASADO",IF(N25<=15,"ATENÇÃO","NO PRAZO")) -> NO PRAZO | P25: c/ usinagem | Q25: =Tabela13[[#This Row],[Data Prev. Fundido]]-10 -> 46239 | R25: AG | S25: AG | T25: AG | U25: AG | V25: AG | W25: AG | X25: AG | Y25: =IF(K25="","AG. FUNDIDO",IF(X25="OK","LIBERADA","EM USINAGEM")) -> AG. FUNDIDO
A26: 1027 | B26: 7 | C26: 27605 | D26: 7 | E26: Água Bonita | F26: 464100 | G26: - | H26: RODETE MOENDA Z15 - 1700 | I26: 1 | J26: 46315 | L26: 46374 | N26: =Tabela13[[#This Row],[Data Prev. Entrega]]-TODAY() -> 155 | O26: =IF(N26<0,"ATRASADO",IF(N26<=15,"ATENÇÃO","NO PRAZO")) -> NO PRAZO | P26: c/ usinagem | Q26: OK | R26: OK | S26: AG | T26: AG | U26: AG | V26: AG | W26: AG | X26: AG | Y26: =IF(K26="","AG. FUNDIDO",IF(X26="OK","LIBERADA","EM USINAGEM")) -> AG. FUNDIDO
A27: 1027 | B27: 8 | C27: 27605 | D27: 8 | E27: Água Bonita | F27: 464100 | G27: - | H27: RODETE MOENDA Z15 - 1700 | I27: 1 | J27: 46315 | L27: 46374 | N27: =Tabela13[[#This Row],[Data Prev. Entrega]]-TODAY() -> 155 | O27: =IF(N27<0,"ATRASADO",IF(N27<=15,"ATENÇÃO","NO PRAZO")) -> NO PRAZO | P27: c/ usinagem | Q27: OK | R27: OK | S27: AG | T27: AG | U27: AG | V27: AG | W27: AG | X27: AG | Y27: =IF(K27="","AG. FUNDIDO",IF(X27="OK","LIBERADA","EM USINAGEM")) -> AG. FUNDIDO
